Workbook
Name Anyela: Hoja1!$F$42:$F$48
Name Anyela_ACUEDUCTO: Hoja1!$I$19:$I$20
Name Anyela_ACUEDUCTO_DESCENTRALIZADO: Hoja1!$I$26:$I$30
Name Anyela_BOMBEROS_DESCENTRALIZADO: Hoja1!$I$45
Name Anyela_Educacion: Hoja1!$I$4:$I$13
Name Anyela_Educación: Hoja1!$I$4:$I$13
Name Anyela_PROPIOS: Hoja1!$I$33:$I$40
Name Anyela_PROPIOS_LUMINARIAS: Hoja1!$I$49
Name Anyela_SALUD: Hoja1!$I$23
Name Dalila: Hoja1!$F$36
Name Dalila_EMPRESA: Hoja1!$I$54
Name Ingrid: Hoja1!$F$23:$F$28
Name Ingrid_ACUEDUCTO: Hoja1!$K$4:$K$8
Name Ingrid_ACUEDUCTO_DESCENTRALIZADO: Hoja1!$K$37:$K$40
Name Ingrid_EDUCACION: Hoja1!$K$51:$K$55
Name Ingrid_PRIVADO: Hoja1!$K$12:$K$34
Name Ingrid_PROPIOS: Hoja1!$K$43:$K$47
Name Ingrid_SALUD: Hoja1!$K$59:$K$63
Name Paola: Hoja1!$F$4:$F$17
Name Paola____SUPERCEL_EU___: Hoja1!$M$3
Name Paola___SIVA_SISTEMA_INTEGRADO_DE_TRANSPORTE: Hoja1!$M$36
Name Paola_ACUEDUCTO: Hoja1!$M$53
Name Paola_EDUCACION: Hoja1!$M$6:$M$7
Name Paola_EMDUPAR: Hoja1!$M$40
Name Paola_FONVISOCIAL: Hoja1!$M$56
Name Paola_HEAD: Hoja1!$M$10
Name Paola_IDECESAR: Hoja1!$M$44
Name Paola_INDER: Hoja1!$M$59
Name Paola_INDER_SEDE_PERMANENTE_12_DE_OCTUBRE_: Hoja1!$M$13
Name Paola_INTERASEO_S.A.E.S.P: Hoja1!$M$47
Name Paola_MERCABASTOS: Hoja1!$M$63
Name Paola_PRIVADO: Hoja1!$M$16:$M$33
Name Paola_PROPIO_SIN_PARQUE: Hoja1!$M$50
Name Roberto: Hoja1!$D$36:$D$41
Name Roberto_ACUEDUCTO_CENTRALIZADO: Hoja1!$O$11
Name Roberto_ACUEDUCTO_DESCENTRALIZADO: Hoja1!$O$3:$O$5
Name Roberto_CENTRALIZADA: Hoja1!$O$31:$O$32
Name Roberto_EDUCACION: Hoja1!$O$20:$O$28
Name Roberto_PRIVADO: Hoja1!$O$8
Name Roberto_PROPIOS: Hoja1!$O$14:$O$17
Name Roberto_SALUD_DESCENTRALIZADO: Hoja1!$O$31:$O$32
Name Rocio: Hoja1!$D$26:$D$31
Name Rocio_ACUEDUCTO: Hoja1!$Q$3:$Q$6
Name Rocio_ACUEDUCTO_DESCENTRALIZADO: Hoja1!$Q$16
Name Rocio_EDUCACION: Hoja1!$Q$122:$Q$128
Name Rocio_OTROS: Hoja1!$Q$9:$Q$13
Name Rocio_PROPIOS: Hoja1!$Q$19:$Q$118
Name Rocio_SALUD: Hoja1!$Q$131:$Q$137
Name Rosmeri: Hoja1!$D$16:$D$20
Name Rosmeri_ACUEDUCTO_DESCENTRALIZADO: Hoja1!$S$3:$S$4
Name Rosmeri_CONCEJO_DESCENTRALIZADO: Hoja1!$S$77
Name Rosmeri_EDUCACION: Hoja1!$S$85:$S$88
Name Rosmeri_PRIVADO: Hoja1!$S$7:$S$73
Name Rosmeri_PROPIOS: Hoja1!$S$81:$S$82
Name SegmentaciónDeDatos_EJECUTIVO: #N/A
Name SegmentaciónDeDatos_SEGMENTO_CUENTA: #N/A
Name SegmentaciónDeDatos_TITULAR_DE_PAGO: #N/A
Name Yeisver: Hoja1!$D$4:$D$10
Name Yeisver_ACUEDUCTO_DESCENTRALIZADO: Hoja1!$U$4
Name Yeisver_ACUEDUCTO_EMPASO_DESCENTRALIZADO: Hoja1!$U$17

Sheet R.V.
A2: EJECUTIVO | B2: NIC | C2: TITULAR DE PAGO | D2: DESCRIPCIÓN DE SUMINISTRO | E2: SEGMENTO_CUENTA | F2: DOBLE ENTREGA (SI/NO) | G2: Donde se entrega PAQUETE 1 | H2: Donde se entrega PAQUETE 2 | I2: OBSERVACION ADICIONAL | K2: filtro | L2: NIC | M2: CRUCE INFOS | N2: CRUCE CENTRALIZADA
A3: Dalila Michela Bracho Acosta | B3: 5312024 | C3: COMERCIALIZADORA COLANTA | D3: PRIVADO | E3: EMPRESA | F3: NO | G3: DG 21, 54 6 P1 LOC 3B CENTRAL DE ABASTOS | K3: Dalila Michela Bracho AcostaCOMERCIALIZADORA COLANTAEMPRESA | L3: 5312024 | N3: =_xlfn.XLOOKUP(L3,CENTRALIZADAS!A:A,CENTRALIZADAS!C:C) -> #N/A
A4: Paola De la Hoz Bastidas | B4: 1413166 | C4: MUNICIPIO DE VALLEDUPAR | D4: ACUEDUCTO CGTO VALENCIA- CARRET VIA PUEBLOBELLO | E4: ACUEDUCTO | F4: NO | G4: CR 5 No.15- 65 Secretraia Gral _Alcaldia Muncipal | I4: Impresión y entrega direcata por Ventas -Territorial, para revisión previa de Facturación, en cumplimiento a compromisos ante la SSPD. | K4: Paola De la Hoz BastidasMUNICIPIO DE VALLEDUPARACUEDUCTO | L4: 1413166 | M4: =_xlfn.XLOOKUP(L4,INFO!F:F,INFO!K:K) -> 50 | N4: =_xlfn.XLOOKUP(L4,CENTRALIZADAS!A:A,CENTRALIZADAS!C:C) -> #N/A
A5: Paola De la Hoz Bastidas | B5: 5357495 | C5: MUNICIPIO DE VALLEDUPAR | D5: ACDTO CMTARIO LAS RAICES_CGTO LAS RAICES | E5: ACUEDUCTO | F5: NO | G5: CR 5 No.15- 65 Secretraia Gral _Alcaldia Muncipal | I5: Impresión y entrega direcata por Ventas -Territorial, para revisión previa de Facturación, en cumplimiento a compromisos ante la SSPD. | K5: Paola De la Hoz BastidasMUNICIPIO DE VALLEDUPARACUEDUCTO | L5: 5357495 | M5: =_xlfn.XLOOKUP(L5,INFO!F:F,INFO!K:K) -> 26 | N5: =_xlfn.XLOOKUP(L5,CENTRALIZADAS!A:A,CENTRALIZADAS!C:C) -> #N/A
A6: Paola De la Hoz Bastidas | B6: 5358999 | C6: MUNICIPIO DE VALLEDUPAR | D6: ACUEDUCTO GUACOCHE_CGTO GUACOCHE | E6: ACUEDUCTO | F6: NO | G6: CR 5 No.15- 65 Secretraia Gral _Alcaldia Muncipal | I6: Impresión y entrega direcata por Ventas -Territorial, para revisión previa de Facturación, en cumplimiento a compromisos ante la SSPD. | K6: Paola De la Hoz BastidasMUNICIPIO DE VALLEDUPARACUEDUCTO | L6: 5358999 | M6: =_xlfn.XLOOKUP(L6,INFO!F:F,INFO!K:K) -> 26 | N6: =_xlfn.XLOOKUP(L6,CENTRALIZADAS!A:A,CENTRALIZADAS!C:C) -> #N/A
A7: Paola De la Hoz Bastidas | B7: 5359176 | C7: MUNICIPIO DE VALLEDUPAR | D7: ACUEDUCTO BOMBA EL JABO_EL JAVO RURAL | E7: ACUEDUCTO | F7: NO | G7: CR 5 No.15- 65 Secretraia Gral _Alcaldia Muncipal | I7: Impresión y entrega direcata por Ventas -Territorial, para revisión previa de Facturación, en cumplimiento a compromisos ante la SSPD. | K7: Paola De la Hoz BastidasMUNICIPIO DE VALLEDUPARACUEDUCTO | L7: 5359176 | M7: =_xlfn.XLOOKUP(L7,INFO!F:F,INFO!K:K) -> 26 | N7: =_xlfn.XLOOKUP(L7,CENTRALIZADAS!A:A,CENTRALIZADAS!C:C) -> #N/A
A8: Paola De la Hoz Bastidas | B8: 5359669 | C8: MUNICIPIO DE VALLEDUPAR | D8: ACUEDUCTO LOS CALABAZOS_CGTO LOS CALABAZOS | E8: ACUEDUCTO | F8: NO | G8: CR 5 No.15- 65 Secretraia Gral _Alcaldia Muncipal | I8: Impresión y entrega direcata por Ventas -Territorial, para revisión previa de Facturación, en cumplimiento a compromisos ante la SSPD. | K8: Paola De la Hoz BastidasMUNICIPIO DE VALLEDUPARACUEDUCTO | L8: 5359669 | M8: =_xlfn.XLOOKUP(L8,INFO!F:F,INFO!K:K) -> 38 | N8: =_xlfn.XLOOKUP(L8,CENTRALIZADAS!A:A,CENTRALIZADAS!C:C) -> #N/A
A9: Paola De la Hoz Bastidas | B9: 5360243 | C9: MUNICIPIO DE VALLEDUPAR | D9: ACUEDUCTO AGUAS BLANCAS_CGTO AGUAS BLANCAS | E9: ACUEDUCTO | F9: NO | G9: CR 5 No.15- 65 Secretraia Gral _Alcaldia Muncipal | I9: Impresión y entrega direcata por Ventas -Territorial, para revisión previa de Facturación, en cumplimiento a compromisos ante la SSPD. | K9: Paola De la Hoz BastidasMUNICIPIO DE VALLEDUPARACUEDUCTO | L9: 5360243 | M9: =_xlfn.XLOOKUP(L9,INFO!F:F,INFO!K:K) -> 27 | N9: =_xlfn.XLOOKUP(L9,CENTRALIZADAS!A:A,CENTRALIZADAS!C:C) -> #N/A
A10: Paola De la Hoz Bastidas | B10: 5360245 | C10: MUNICIPIO DE VALLEDUPAR | D10: ACUEDUCTO AGUAS BLANCAS_CGTO AGUAS BLANCAS | E10: ACUEDUCTO | F10: NO | G10: CR 5 No.15- 65 Secretraia Gral _Alcaldia Muncipal | I10: Impresión y entrega direcata por Ventas -Territorial, para revisión previa de Facturación, en cumplimiento a compromisos ante la SSPD. | K10: Paola De la Hoz BastidasMUNICIPIO DE VALLEDUPARACUEDUCTO | L10: 5360245 | M10: =_xlfn.XLOOKUP(L10,INFO!F:F,INFO!K:K) -> 27 | N10: =_xlfn.XLOOKUP(L10,CENTRALIZADAS!A:A,CENTRALIZADAS!C:C) -> #N/A
A11: Paola De la Hoz Bastidas | B11: 5361891 | C11: MUNICIPIO DE VALLEDUPAR | D11: ACUEDUCTO GUAYMARAL_CGTO GUAIMARAL | E11: ACUEDUCTO | F11: NO | G11: CR 5 No.15- 65 Secretraia Gral _Alcaldia Muncipal | I11: Impresión y entrega direcata por Ventas -Territorial, para revisión previa de Facturación, en cumplimiento a compromisos ante la SSPD. | K11: Paola De la Hoz BastidasMUNICIPIO DE VALLEDUPARACUEDUCTO | L11: 5361891 | M11: =_xlfn.XLOOKUP(L11,INFO!F:F,INFO!K:K) -> 27 | N11: =_xlfn.XLOOKUP(L11,CENTRALIZADAS!A:A,CENTRALIZADAS!C:C) -> #N/A
A12: Paola De la Hoz Bastidas | B12: 5361969 | C12: MUNICIPIO DE VALLEDUPAR | D12: ACUEDUCTO SAN MARTIN_CGTO EL PERRO | E12: ACUEDUCTO | F12: NO | G12: CR 5 No.15- 65 Secretraia Gral _Alcaldia Muncipal | I12: Impresión y entrega direcata por Ventas -Territorial, para revisión previa de Facturación, en cumplimiento a compromisos ante la SSPD. | K12: Paola De la Hoz BastidasMUNICIPIO DE VALLEDUPARACUEDUCTO | L12: 5361969 | M12: =_xlfn.XLOOKUP(L12,INFO!F:F,INFO!K:K) -> 27 | N12: =_xlfn.XLOOKUP(L12,CENTRALIZADAS!A:A,CENTRALIZADAS!C:C) -> #N/A
A13: Paola De la Hoz Bastidas | B13: 6238148 | C13: MUNICIPIO DE VALLEDUPAR | D13: ACDTO BOMBA LA VEGA _CGTO LA VEGA ARRIBA | E13: ACUEDUCTO | F13: NO | G13: CR 5 No.15- 65 Secretraia Gral _Alcaldia Muncipal | I13: Impresión y entrega direcata por Ventas -Territorial, para revisión previa de Facturación, en cumplimiento a compromisos ante la SSPD. | K13: Paola De la Hoz BastidasMUNICIPIO DE VALLEDUPARACUEDUCTO | L13: 6238148 | M13: =_xlfn.XLOOKUP(L13,INFO!F:F,INFO!K:K) -> 38 | N13: =_xlfn.XLOOKUP(L13,CENTRALIZADAS!A:A,CENTRALIZADAS!C:C) -> #N/A
A14: Paola De la Hoz Bastidas | B14: 6634302 | C14: MUNICIPIO DE VALLEDUPAR | D14: ACUEDUCTO DE ATANQUEZ_CGTO ATANQUEZ | E14: ACUEDUCTO | F14: NO | G14: CR 5 No.15- 65 Secretraia Gral _Alcaldia Muncipal | I14: Impresión y entrega direcata por Ventas -Territorial, para revisión previa de Facturación, en cumplimiento a compromisos ante la SSPD. | K14: Paola De la Hoz BastidasMUNICIPIO DE VALLEDUPARACUEDUCTO | L14: 6634302 | M14: =_xlfn.XLOOKUP(L14,INFO!F:F,INFO!K:K) -> 26 | N14: =_xlfn.XLOOKUP(L14,CENTRALIZADAS!A:A,CENTRALIZADAS!C:C) -> #N/A
A15: Paola De la Hoz Bastidas | B15: 6634330 | C15: MUNICIPIO DE VALLEDUPAR | D15: POZOS PROFUNDOS LAS CASITAS_VALLEDUPAR | E15: ACUEDUCTO | F15: NO | G15: CR 5 No.15- 65 Secretraia Gral _Alcaldia Muncipal | I15: Impresión y entrega direcata por Ventas -Territorial, para revisión previa de Facturación, en cumplimiento a compromisos ante la SSPD. | K15: Paola De la Hoz BastidasMUNICIPIO DE VALLEDUPARACUEDUCTO | L15: 6634330 | M15: =_xlfn.XLOOKUP(L15,INFO!F:F,INFO!K:K) -> 10 | N15: =_xlfn.XLOOKUP(L15,CENTRALIZADAS!A:A,CENTRALIZADAS!C:C) -> #N/A
... A332: Paola De la Hoz Bastidas | B332: 7958047 | C332: MUNICIPIO DE VALLEDUPAR | D332: PARQUE LA PROVINCIA_VALLEDUPAR | E332: MERCABASTOS | F332: NO | G332: CR 5 No.15- 65 Secretraia Gral _Alcaldia Muncipal | I332: Impresión y entrega direcata por Ventas -Territorial, para revisión previa de Facturación, en cumplimiento a compromisos ante la SSPD. | K332: Paola De la Hoz BastidasMUNICIPIO DE VALLEDUPARMERCABASTOS | L332: 7958047 | M332: =_xlfn.XLOOKUP(L332,INFO!F:F,INFO!K:K) -> 50 | N332: =_xlfn.XLOOKUP(L332,CENTRALIZADAS!A:A,CENTRALIZADAS!C:C) -> #N/A
A333: Paola De la Hoz Bastidas | B333: 5300000 | C333: HOSPITAL EDUARDO ARREDONDO DAZA | D333: PUESTO DE SALUD DE LA MESA- | E333: HEAD | F333: NO | G333: CL 44, 20 30 PUESTO DE SALUD VILLA LEONOR VILLA LEONOR VALLEDUPAR | K333: Paola De la Hoz BastidasHOSPITAL EDUARDO ARREDONDO DAZAHEAD | L333: 5300000 | N333: =_xlfn.XLOOKUP(L333,CENTRALIZADAS!A:A,CENTRALIZADAS!C:C) -> #N/A
A334: Paola De la Hoz Bastidas | B334: 5300010 | C334: HOSPITAL EDUARDO ARREDONDO DAZA | D334: PTO. SALUD B. EL CARMEN | E334: HEAD | F334: NO | G334: CL 44, 20 30 PUESTO DE SALUD VILLA LEONOR VILLA LEONOR VALLEDUPAR | K334: Paola De la Hoz BastidasHOSPITAL EDUARDO ARREDONDO DAZAHEAD | L334: 5300010 | N334: =_xlfn.XLOOKUP(L334,CENTRALIZADAS!A:A,CENTRALIZADAS!C:C) -> #N/A
A335: Paola De la Hoz Bastidas | B335: 5300017 | C335: HOSPITAL EDUARDO ARREDONDO DAZA | D335: PUESTO DE SALUD C.D.V. MANANTIAL | E335: HEAD | F335: NO | G335: CL 44, 20 30 PUESTO DE SALUD VILLA LEONOR VILLA LEONOR VALLEDUPAR | K335: Paola De la Hoz BastidasHOSPITAL EDUARDO ARREDONDO DAZAHEAD | L335: 5300017 | N335: =_xlfn.XLOOKUP(L335,CENTRALIZADAS!A:A,CENTRALIZADAS!C:C) -> #N/A
A336: Paola De la Hoz Bastidas | B336: 5302684 | C336: HOSPITAL EDUARDO ARREDONDO DAZA | D336: PUESTO DE SALUD DE RIO SECO | E336: HEAD | F336: NO | G336: CL 44, 20 30 PUESTO DE SALUD VILLA LEONOR VILLA LEONOR VALLEDUPAR | K336: Paola De la Hoz BastidasHOSPITAL EDUARDO ARREDONDO DAZAHEAD | L336: 5302684 | N336: =_xlfn.XLOOKUP(L336,CENTRALIZADAS!A:A,CENTRALIZADAS!C:C) -> #N/A
A337: Paola De la Hoz Bastidas | B337: 5303424 | C337: HOSPITAL EDUARDO ARREDONDO DAZA | D337: PUESTO DE SALUD VICTORIA | E337: HEAD | F337: NO | G337: CL 44, 20 30 PUESTO DE SALUD VILLA LEONOR VILLA LEONOR VALLEDUPAR | K337: Paola De la Hoz BastidasHOSPITAL EDUARDO ARREDONDO DAZAHEAD | L337: 5303424 | N337: =_xlfn.XLOOKUP(L337,CENTRALIZADAS!A:A,CENTRALIZADAS!C:C) -> #N/A
A338: Paola De la Hoz Bastidas | B338: 5308710 | C338: HOSPITAL EDUARDO ARREDONDO DAZA | D338: PUESTO DE SALUD LA NEVADA | E338: HEAD | F338: NO | G338: CL 44, 20 30 PUESTO DE SALUD VILLA LEONOR VILLA LEONOR VALLEDUPAR | K338: Paola De la Hoz BastidasHOSPITAL EDUARDO ARREDONDO DAZAHEAD | L338: 5308710 | N338: =_xlfn.XLOOKUP(L338,CENTRALIZADAS!A:A,CENTRALIZADAS!C:C) -> #N/A
A339: Paola De la Hoz Bastidas | B339: 5309634 | C339: HOSPITAL EDUARDO ARREDONDO DAZA | D339: HOSPITAL EDO. ARREDONDO DAZA -VILLALEONOR | E339: HEAD | F339: NO | G339: CL 44, 20 30 PUESTO DE SALUD VILLA LEONOR VILLA LEONOR VALLEDUPAR | K339: Paola De la Hoz BastidasHOSPITAL EDUARDO ARREDONDO DAZAHEAD | L339: 5309634 | N339: =_xlfn.XLOOKUP(L339,CENTRALIZADAS!A:A,CENTRALIZADAS!C:C) -> #N/A
A340: Paola De la Hoz Bastidas | B340: 5313114 | C340: HOSPITAL EDUARDO ARREDONDO DAZA | D340: PUESTO DE SALUD LAS VEGAS | E340: HEAD | F340: NO | G340: CL 44, 20 30 PUESTO DE SALUD VILLA LEONOR VILLA LEONOR VALLEDUPAR | K340: Paola De la Hoz BastidasHOSPITAL EDUARDO ARREDONDO DAZAHEAD | L340: 5313114 | N340: =_xlfn.XLOOKUP(L340,CENTRALIZADAS!A:A,CENTRALIZADAS!C:C) -> #N/A
A341: Paola De la Hoz Bastidas | B341: 5319050 | C341: HOSPITAL EDUARDO ARREDONDO DAZA | D341: PUESTO DE SALUD GUACOCHE | E341: HEAD | F341: NO | G341: CL 44, 20 30 PUESTO DE SALUD VILLA LEONOR VILLA LEONOR VALLEDUPAR | K341: Paola De la Hoz BastidasHOSPITAL EDUARDO ARREDONDO DAZAHEAD | L341: 5319050 | N341: =_xlfn.XLOOKUP(L341,CENTRALIZADAS!A:A,CENTRALIZADAS!C:C) -> #N/A
A342: Paola De la Hoz Bastidas | B342: 5354933 | C342: HOSPITAL EDUARDO ARREDONDO DAZA | D342: PUESTO DE SALUD SAN JOAQUIN | E342: HEAD | F342: NO | G342: CL 44, 20 30 PUESTO DE SALUD VILLA LEONOR VILLA LEONOR VALLEDUPAR | K342: Paola De la Hoz BastidasHOSPITAL EDUARDO ARREDONDO DAZAHEAD | L342: 5354933 | N342: =_xlfn.XLOOKUP(L342,CENTRALIZADAS!A:A,CENTRALIZADAS!C:C) -> #N/A
A343: Paola De la Hoz Bastidas | B343: 5357269 | C343: HOSPITAL EDUARDO ARREDONDO DAZA | D343: PUESTO DE SALUD PATILLAL | E343: HEAD | F343: NO | G343: CL 44, 20 30 PUESTO DE SALUD VILLA LEONOR VILLA LEONOR VALLEDUPAR | K343: Paola De la Hoz BastidasHOSPITAL EDUARDO ARREDONDO DAZAHEAD | L343: 5357269 | N343: =_xlfn.XLOOKUP(L343,CENTRALIZADAS!A:A,CENTRALIZADAS!C:C) -> #N/A
A344: Paola De la Hoz Bastidas | B344: 5357554 | C344: HOSPITAL EDUARDO ARREDONDO DAZA | D344: PUESTO DE SALUD LA MINA | E344: HEAD | F344: NO | G344: CL 44, 20 30 PUESTO DE SALUD VILLA LEONOR VILLA LEONOR VALLEDUPAR | K344: Paola De la Hoz BastidasHOSPITAL EDUARDO ARREDONDO DAZAHEAD | L344: 5357554 | N344: =_xlfn.XLOOKUP(L344,CENTRALIZADAS!A:A,CENTRALIZADAS!C:C) -> #N/A
... A414: Paola De la Hoz Bastidas | B414: 5330743 | C414: SAS HOTEL UCLA CENTER CONS EN GESTION FINANCIERA Y DE RES | D414: SAS HOTEL UCLA CENTER CONS EN GESTION FINANCIERA Y DE RES | E414: PRIVADO | F414: NO | G414: CL 22C 18A 31 _SIMON BOLIVAR | K414: Paola De la Hoz BastidasSAS HOTEL UCLA CENTER CONS EN GESTION FINANCIERA Y DE RESPRIVADO | L414: 5330743 | N414: =_xlfn.XLOOKUP(L414,CENTRALIZADAS!A:A,CENTRALIZADAS!C:C) -> #N/A
A415: Paola De la Hoz Bastidas | B415: 5302399 | C415: FAMISANAR ENTIDAD PROMOTORA DE SALUD | D415: FAMISANAR ENTIDAD PROMOTORA DE SALUD | E415: EDUCACION | F415: NO | G415: CL 17 12 74 _LOPERENA | I415: Centralizada | K415: Paola De la Hoz BastidasFAMISANAR ENTIDAD PROMOTORA DE SALUDEDUCACION | L415: 5302399 | N415: =_xlfn.XLOOKUP(L415,CENTRALIZADAS!A:A,CENTRALIZADAS!C:C) -> SSGMTO
A416: Roberto Pavajeau Hernandez | B416: 5802788 | C416: Municipio de Algarrobo | D416: COL DPAL RAFAEL NUÑEZ | E416: EDUCACION | F416: NO | G416: Carrera 9 # 8 - 44 - Parque Central, Algarrobo-Magdalena | K416: Roberto Pavajeau HernandezMunicipio de AlgarroboEDUCACION | L416: 5802788 | N416: =_xlfn.XLOOKUP(L416,CENTRALIZADAS!A:A,CENTRALIZADAS!C:C) -> #N/A
A417: Roberto Pavajeau Hernandez | B417: 5808911 | C417: Municipio de Algarrobo | D417: COLE DPTAL 26 DE JULIO | E417: EDUCACION | F417: NO | G417: Carrera 9 # 8 - 44 - Parque Central, Algarrobo-Magdalena | K417: Roberto Pavajeau HernandezMunicipio de AlgarroboEDUCACION | L417: 5808911 | N417: =_xlfn.XLOOKUP(L417,CENTRALIZADAS!A:A,CENTRALIZADAS!C:C) -> #N/A
A418: Roberto Pavajeau Hernandez | B418: 5809128 | C418: Municipio de Algarrobo | D418: INS EDUCATIVO ALGARROBO | E418: EDUCACION | F418: NO | G418: Carrera 9 # 8 - 44 - Parque Central, Algarrobo-Magdalena | K418: Roberto Pavajeau HernandezMunicipio de AlgarroboEDUCACION | L418: 5809128 | N418: =_xlfn.XLOOKUP(L418,CENTRALIZADAS!A:A,CENTRALIZADAS!C:C) -> #N/A
A419: Roberto Pavajeau Hernandez | B419: 5809277 | C419: Municipio de Algarrobo | D419: COLEGIO MIRAFLOREZ | E419: EDUCACION | F419: NO | G419: Carrera 9 # 8 - 44 - Parque Central, Algarrobo-Magdalena | K419: Roberto Pavajeau HernandezMunicipio de AlgarroboEDUCACION | L419: 5809277 | N419: =_xlfn.XLOOKUP(L419,CENTRALIZADAS!A:A,CENTRALIZADAS!C:C) -> #N/A
A420: Roberto Pavajeau Hernandez | B420: 5809837 | C420: Municipio de Algarrobo | D420: COL SAGRADO CORAZÓN | E420: EDUCACION | F420: NO | G420: Carrera 9 # 8 - 44 - Parque Central, Algarrobo-Magdalena | K420: Roberto Pavajeau HernandezMunicipio de AlgarroboEDUCACION | L420: 5809837 | N420: =_xlfn.XLOOKUP(L420,CENTRALIZADAS!A:A,CENTRALIZADAS!C:C) -> #N/A
A421: Roberto Pavajeau Hernandez | B421: 5809970 | C421: Municipio de Algarrobo | D421: ESC LOMA DEL BALSAMO | E421: EDUCACION | F421: NO | G421: Carrera 9 # 8 - 44 - Parque Central, Algarrobo-Magdalena | K421: Roberto Pavajeau HernandezMunicipio de AlgarroboEDUCACION | L421: 5809970 | N421: =_xlfn.XLOOKUP(L421,CENTRALIZADAS!A:A,CENTRALIZADAS!C:C) -> #N/A
A422: Roberto Pavajeau Hernandez | B422: 6316672 | C422: Municipio de Algarrobo | D422: COLE MARIA AUXILIADORA | E422: EDUCACION | F422: NO | G422: Carrera 9 # 8 - 44 - Parque Central, Algarrobo-Magdalena | K422: Roberto Pavajeau HernandezMunicipio de AlgarroboEDUCACION | L422: 6316672 | N422: =_xlfn.XLOOKUP(L422,CENTRALIZADAS!A:A,CENTRALIZADAS!C:C) -> #N/A
A423: Roberto Pavajeau Hernandez | B423: 6649200 | C423: Municipio de Algarrobo | D423: LA LOMA DEL BALSAMO ZONA RURAL | E423: EDUCACION | F423: NO | G423: Carrera 9 # 8 - 44 - Parque Central, Algarrobo-Magdalena | K423: Roberto Pavajeau HernandezMunicipio de AlgarroboEDUCACION | L423: 6649200 | N423: =_xlfn.XLOOKUP(L423,CENTRALIZADAS!A:A,CENTRALIZADAS!C:C) -> #N/A
A424: Roberto Pavajeau Hernandez | B424: 6892346 | C424: Municipio de Algarrobo | D424: CENTRO EDUCATIVO ESTACIÓN LLERAS | E424: EDUCACION | F424: NO | G424: Carrera 9 # 8 - 44 - Parque Central, Algarrobo-Magdalena | K424: Roberto Pavajeau HernandezMunicipio de AlgarroboEDUCACION | L424: 6892346 | N424: =_xlfn.XLOOKUP(L424,CENTRALIZADAS!A:A,CENTRALIZADAS!C:C) -> #N/A
A425: Roberto Pavajeau Hernandez | B425: 6918563 | C425: Municipio de Algarrobo | D425: ESC INMACULADA CONCEPCIÓN RIOMAR | E425: EDUCACION | F425: NO | G425: Carrera 9 # 8 - 44 - Parque Central, Algarrobo-Magdalena | K425: Roberto Pavajeau HernandezMunicipio de AlgarroboEDUCACION | L425: 6918563 | N425: =_xlfn.XLOOKUP(L425,CENTRALIZADAS!A:A,CENTRALIZADAS!C:C) -> #N/A
A426: Roberto Pavajeau Hernandez | B426: 7502742 | C426: Municipio de Algarrobo | D426: ESC RAFAEL NUÑEZ | E426: EDUCACION | F426: NO | G426: Carrera 9 # 8 - 44 - Parque Central, Algarrobo-Magdalena | K426: Roberto Pavajeau HernandezMunicipio de AlgarroboEDUCACION | L426: 7502742 | N426: =_xlfn.XLOOKUP(L426,CENTRALIZADAS!A:A,CENTRALIZADAS!C:C) -> #N/A
...

Sheet Relación Valorada
D1: FORMATO ENTREGA FACTURACIÓN ESPECIAL
J3: Rosmeri
A4: ALIADO COMERCIAL: | D4: INMEL | E4: REPARTIDOR ASIGNADO:
J5: =J6&D6&D10 -> Rosmeri Rivera RodriguezMUNICIPIO DE LA PAZEDUCACION
A6: TITULAR DE PAGO: | D6: MUNICIPIO DE LA PAZ | J6: {=_xlfn.IFS(J3="Anyela","Anyela Maria Gutierrez Ochoa",J3="Dalila","Dalila Michela Bracho Acosta",J3="Ingrid","Ingrid Johana Giraldo Quinonez",J3="Paola","Paola De la Hoz Bastidas",J3="Roberto","Roberto Pavajeau Hernandez",J3="Rocio","Rocio Gutierrez Ochoa",J3="Rosmeri","Rosmeri Rivera Rodriguez",J3="Yeisver","Yeisver Jimenéz Quiroz")} -> Rosmeri Rivera Rodriguez
A8: DIRECCION: | D8: =IFERROR(VLOOKUP(C13,[1]INFO!A:E,5,0)," ") -> CENTRO LA PAZ CR 9 6-36
A10: SEGMENTO / CUENTA: | D10: EDUCACION
A12: Nº | C12: NIC | D12: DESCRIPCION DE SUMINISTRO | E12: SIMB VAR | F12: IMPORTE MES | G12: DEUDA | H12: TOTAL
A13: 1 | B13: {=_xlfn._xlws.FILTER('R.V.'!K3:L2141,'R.V.'!K3:K2141=J5,"error")} -> Rosmeri Rivera RodriguezMUNICIPIO DE LA PAZEDUCACION | C13: 5819128 | D13: =IFERROR(VLOOKUP(C13,'R.V.'!B:D,3,0)," ") -> ESCUELA DE VARAS BLANCAS | E13: =IFERROR(VLOOKUP($C13,INFO!$F:$AK,2,0)," ") -> 5819128328 | F13: =IFERROR(VLOOKUP(C13,INFO!F:T,11,0)," ") -> 231580 | G13: =IFERROR(H13-F13," ") -> 205010 | H13: =IFERROR(VLOOKUP(C13,INFO!$F:$AK,32,0)," ") -> 436590
A14: 2 | B14: Rosmeri Rivera RodriguezMUNICIPIO DE LA PAZEDUCACION | C14: 5839301 | D14: =IFERROR(VLOOKUP(C14,'R.V.'!B:D,3,0)," ") -> COLEGIO 19 DE MARZO F | E14: =IFERROR(VLOOKUP($C14,INFO!$F:$AK,2,0)," ") -> 5839301298 | F14: =IFERROR(VLOOKUP(C14,INFO!F:T,11,0)," ") -> 609960 | G14: =IFERROR(H14-F14," ") -> 332650 | H14: =IFERROR(VLOOKUP(C14,INFO!$F:$AK,32,0)," ") -> 942610
A15: 3 | B15: Rosmeri Rivera RodriguezMUNICIPIO DE LA PAZEDUCACION | C15: 5839391 | D15: =IFERROR(VLOOKUP(C15,'R.V.'!B:D,3,0)," ") -> ESCUELA URBANA MINAS F | E15: =IFERROR(VLOOKUP($C15,INFO!$F:$AK,2,0)," ") -> 5839391323 | F15: =IFERROR(VLOOKUP(C15,INFO!F:T,11,0)," ") -> 502970 | G15: =IFERROR(H15-F15," ") -> 379730 | H15: =IFERROR(VLOOKUP(C15,INFO!$F:$AK,32,0)," ") -> 882700
A16: 4 | B16: Rosmeri Rivera RodriguezMUNICIPIO DE LA PAZEDUCACION | C16: 5839519 | D16: =IFERROR(VLOOKUP(C16,'R.V.'!B:D,3,0)," ") -> ESCUELA DE VARONES | E16: =IFERROR(VLOOKUP($C16,INFO!$F:$AK,2,0)," ") -> 5839519298 | F16: =IFERROR(VLOOKUP(C16,INFO!F:T,11,0)," ") -> 358710 | G16: =IFERROR(H16-F16," ") -> 297840 | H16: =IFERROR(VLOOKUP(C16,INFO!$F:$AK,32,0)," ") -> 656550
A17: 5 | B17: Rosmeri Rivera RodriguezMUNICIPIO DE LA PAZEDUCACION | C17: 5839954 | D17: =IFERROR(VLOOKUP(C17,'R.V.'!B:D,3,0)," ") -> ESCUELA URBANA LA FLORIDA | E17: =IFERROR(VLOOKUP($C17,INFO!$F:$AK,2,0)," ") -> 5839954258 | F17: =IFERROR(VLOOKUP(C17,INFO!F:T,11,0)," ") -> 1438800 | G17: =IFERROR(H17-F17," ") -> 1167980 | H17: =IFERROR(VLOOKUP(C17,INFO!$F:$AK,32,0)," ") -> 2606780
A18: 6 | B18: Rosmeri Rivera RodriguezMUNICIPIO DE LA PAZEDUCACION | C18: 5840080 | D18: =IFERROR(VLOOKUP(C18,'R.V.'!B:D,3,0)," ") -> COLEGIO CIRO PUPO MARTINEZ | E18: =IFERROR(VLOOKUP($C18,INFO!$F:$AK,2,0)," ") -> 5840080327 | F18: =IFERROR(VLOOKUP(C18,INFO!F:T,11,0)," ") -> 4980630 | G18: =IFERROR(H18-F18," ") -> 4148850 | H18: =IFERROR(VLOOKUP(C18,INFO!$F:$AK,32,0)," ") -> 9129480
A19: 7 | B19: Rosmeri Rivera RodriguezMUNICIPIO DE LA PAZEDUCACION | C19: 5840113 | D19: =IFERROR(VLOOKUP(C19,'R.V.'!B:D,3,0)," ") -> COLEGIO ALFONSO ARAUJO | E19: =IFERROR(VLOOKUP($C19,INFO!$F:$AK,2,0)," ") -> 5840113327 | F19: =IFERROR(VLOOKUP(C19,INFO!F:T,11,0)," ") -> 935850 | G19: =IFERROR(H19-F19," ") -> 589600 | H19: =IFERROR(VLOOKUP(C19,INFO!$F:$AK,32,0)," ") -> 1525450
A20: 8 | B20: Rosmeri Rivera RodriguezMUNICIPIO DE LA PAZEDUCACION | C20: 5840343 | D20: =IFERROR(VLOOKUP(C20,'R.V.'!B:D,3,0)," ") -> ESCUELA LAS DELICIAS | E20: =IFERROR(VLOOKUP($C20,INFO!$F:$AK,2,0)," ") -> 5840343307 | F20: =IFERROR(VLOOKUP(C20,INFO!F:T,11,0)," ") -> 143780 | G20: =IFERROR(H20-F20," ") -> 94290 | H20: =IFERROR(VLOOKUP(C20,INFO!$F:$AK,32,0)," ") -> 238070
A21: 9 | B21: Rosmeri Rivera RodriguezMUNICIPIO DE LA PAZEDUCACION | C21: 5840854 | D21: =IFERROR(VLOOKUP(C21,'R.V.'!B:D,3,0)," ") -> ESCUELA FRAY JOAQUIN F | E21: =IFERROR(VLOOKUP($C21,INFO!$F:$AK,2,0)," ") -> 5840854331 | F21: =IFERROR(VLOOKUP(C21,INFO!F:T,11,0)," ") -> 542310 | G21: =IFERROR(H21-F21," ") -> 522160 | H21: =IFERROR(VLOOKUP(C21,INFO!$F:$AK,32,0)," ") -> 1064470
A22: 10 | B22: Rosmeri Rivera RodriguezMUNICIPIO DE LA PAZEDUCACION | C22: 5858000 | D22: =IFERROR(VLOOKUP(C22,'R.V.'!B:D,3,0)," ") -> COLEGIO MIXTO - SAN JOSE DE ORIENTE | E22: =IFERROR(VLOOKUP($C22,INFO!$F:$AK,2,0)," ") -> 5858000345 | F22: =IFERROR(VLOOKUP(C22,INFO!F:T,11,0)," ") -> 203270 | G22: =IFERROR(H22-F22," ") -> 150020 | H22: =IFERROR(VLOOKUP(C22,INFO!$F:$AK,32,0)," ") -> 353290
A23: 11 | B23: Rosmeri Rivera RodriguezMUNICIPIO DE LA PAZEDUCACION | C23: 5858193 | D23: =IFERROR(VLOOKUP(C23,'R.V.'!B:D,3,0)," ") -> COLEGIO COOPERATIVO SAN JOSE DE ORIENTE | E23: =IFERROR(VLOOKUP($C23,INFO!$F:$AK,2,0)," ") -> 5858193329 | F23: =IFERROR(VLOOKUP(C23,INFO!F:T,11,0)," ") -> 1807220 | G23: =IFERROR(H23-F23," ") -> 959430 | H23: =IFERROR(VLOOKUP(C23,INFO!$F:$AK,32,0)," ") -> 2766650
A24: 12 | B24: Rosmeri Rivera RodriguezMUNICIPIO DE LA PAZEDUCACION | C24: 6639172 | D24: =IFERROR(VLOOKUP(C24,'R.V.'!B:D,3,0)," ") -> COLEGIO TECNICO AGROPECUARIO BETANIA | E24: =IFERROR(VLOOKUP($C24,INFO!$F:$AK,2,0)," ") -> 6639172264 | F24: =IFERROR(VLOOKUP(C24,INFO!F:T,11,0)," ") -> 259790 | G24: =IFERROR(H24-F24," ") -> 195610 | H24: =IFERROR(VLOOKUP(C24,INFO!$F:$AK,32,0)," ") -> 455400
A25: 13 | B25: Rosmeri Rivera RodriguezMUNICIPIO DE LA PAZEDUCACION | C25: 6658036 | D25: =IFERROR(VLOOKUP(C25,'R.V.'!B:D,3,0)," ") -> COLEGIO VEREDA LA LAGUNA SAN JOSE DE ORIENTE | E25: =IFERROR(VLOOKUP($C25,INFO!$F:$AK,2,0)," ") -> 6658036263 | F25: =IFERROR(VLOOKUP(C25,INFO!F:T,11,0)," ") -> 33300 | G25: =IFERROR(H25-F25," ") -> 51070 | H25: =IFERROR(VLOOKUP(C25,INFO!$F:$AK,32,0)," ") -> 84370
... A39: 27 | B39: Rosmeri Rivera RodriguezMUNICIPIO DE LA PAZEDUCACION | C39: 1380305 | D39: =IFERROR(VLOOKUP(C39,'R.V.'!B:D,3,0)," ") -> COLEGIO CIRO PUPO MARTINEZ | E39: =IFERROR(VLOOKUP($C39,INFO!$F:$AK,2,0)," ") -> 1380305024 | F39: =IFERROR(VLOOKUP(C39,INFO!F:T,11,0)," ") -> 1731000 | G39: =IFERROR(H39-F39," ") -> 1384600 | H39: =IFERROR(VLOOKUP(C39,INFO!$F:$AK,32,0)," ") -> 3115600
A40: 28 | D40: =IFERROR(VLOOKUP(C40,'R.V.'!B:D,3,0)," ") | E40: =IFERROR(VLOOKUP($C40,INFO!$F:$AK,2,0)," ") | F40: =IFERROR(VLOOKUP(C40,INFO!F:T,11,0)," ") | G40: =IFERROR(H40-F40," ") | H40: =IFERROR(VLOOKUP(C40,INFO!$F:$AK,32,0)," ")
A41: 29 | D41: =IFERROR(VLOOKUP(C41,'R.V.'!B:D,3,0)," ") | E41: =IFERROR(VLOOKUP($C41,INFO!$F:$AK,2,0)," ") | F41: =IFERROR(VLOOKUP(C41,INFO!F:T,11,0)," ") | G41: =IFERROR(H41-F41," ") | H41: =IFERROR(VLOOKUP(C41,INFO!$F:$AK,32,0)," ")
A42: 30 | D42: =IFERROR(VLOOKUP(C42,'R.V.'!B:D,3,0)," ") | E42: =IFERROR(VLOOKUP($C42,INFO!$F:$AK,2,0)," ") | F42: =IFERROR(VLOOKUP(C42,INFO!F:T,11,0)," ") | G42: =IFERROR(H42-F42," ") | H42: =IFERROR(VLOOKUP(C42,INFO!$F:$AK,32,0)," ")
A43: 31 | D43: =IFERROR(VLOOKUP(C43,'R.V.'!B:D,3,0)," ") | E43: =IFERROR(VLOOKUP($C43,INFO!$F:$AK,2,0)," ") | F43: =IFERROR(VLOOKUP(C43,INFO!F:T,11,0)," ") | G43: =IFERROR(H43-F43," ") | H43: =IFERROR(VLOOKUP(C43,INFO!$F:$AK,32,0)," ")
A44: 32 | D44: =IFERROR(VLOOKUP(C44,'R.V.'!B:D,3,0)," ") | E44: =IFERROR(VLOOKUP($C44,INFO!$F:$AK,2,0)," ") | F44: =IFERROR(VLOOKUP(C44,INFO!F:T,11,0)," ") | G44: =IFERROR(H44-F44," ") | H44: =IFERROR(VLOOKUP(C44,INFO!$F:$AK,32,0)," ")
A45: 33 | D45: =IFERROR(VLOOKUP(C45,'R.V.'!B:D,3,0)," ") | E45: =IFERROR(VLOOKUP($C45,INFO!$F:$AK,2,0)," ") | F45: =IFERROR(VLOOKUP(C45,INFO!F:T,11,0)," ") | G45: =IFERROR(H45-F45," ") | H45: =IFERROR(VLOOKUP(C45,INFO!$F:$AK,32,0)," ")
A46: 34 | D46: =IFERROR(VLOOKUP(C46,'R.V.'!B:D,3,0)," ") | E46: =IFERROR(VLOOKUP($C46,INFO!$F:$AK,2,0)," ") | F46: =IFERROR(VLOOKUP(C46,INFO!F:T,11,0)," ") | G46: =IFERROR(H46-F46," ") | H46: =IFERROR(VLOOKUP(C46,INFO!$F:$AK,32,0)," ")
A47: 35 | D47: =IFERROR(VLOOKUP(C47,'R.V.'!B:D,3,0)," ") | E47: =IFERROR(VLOOKUP($C47,INFO!$F:$AK,2,0)," ") | F47: =IFERROR(VLOOKUP(C47,INFO!F:T,11,0)," ") | G47: =IFERROR(H47-F47," ") | H47: =IFERROR(VLOOKUP(C47,INFO!$F:$AK,32,0)," ")
A48: 36 | D48: =IFERROR(VLOOKUP(C48,'R.V.'!B:D,3,0)," ") | E48: =IFERROR(VLOOKUP($C48,INFO!$F:$AK,2,0)," ") | F48: =IFERROR(VLOOKUP(C48,INFO!F:T,11,0)," ") | G48: =IFERROR(H48-F48," ") | H48: =IFERROR(VLOOKUP(C48,INFO!$F:$AK,32,0)," ")
A49: 37 | D49: =IFERROR(VLOOKUP(C49,'R.V.'!B:D,3,0)," ") | E49: =IFERROR(VLOOKUP($C49,INFO!$F:$AK,2,0)," ") | F49: =IFERROR(VLOOKUP(C49,INFO!F:T,11,0)," ") | G49: =IFERROR(H49-F49," ") | H49: =IFERROR(VLOOKUP(C49,INFO!$F:$AK,32,0)," ")
A50: 38 | D50: =IFERROR(VLOOKUP(C50,'R.V.'!B:D,3,0)," ") | E50: =IFERROR(VLOOKUP($C50,INFO!$F:$AK,2,0)," ") | F50: =IFERROR(VLOOKUP(C50,INFO!F:T,11,0)," ") | G50: =IFERROR(H50-F50," ") | H50: =IFERROR(VLOOKUP(C50,INFO!$F:$AK,32,0)," ")
A51: 39 | D51: =IFERROR(VLOOKUP(C51,'R.V.'!B:D,3,0)," ") | E51: =IFERROR(VLOOKUP($C51,INFO!$F:$AK,2,0)," ") | F51: =IFERROR(VLOOKUP(C51,INFO!F:T,11,0)," ") | G51: =IFERROR(H51-F51," ") | H51: =IFERROR(VLOOKUP(C51,INFO!$F:$AK,32,0)," ")
E52: TOTAL | F52: =SUM(F13:F51) -> 14497590 | G52: =SUM(G13:G51) -> 8857888 | H52: =SUM(H13:H51) -> 23355478
A54: A CARIBEMAR DE LA COSTA S.A.S. E.S.P., le son aplicables las normas que regulan el saneamiento contable en el sector público, por tanto, nos permitimos recordar la obligacion que nos asiste de reportar a la Contaduría General de la Nación, semestralmente el Boletín de Deudores Morosos del Estado - BDME - , y trimestralmente el informe de Recíprocas (Entidades oficiales), los cuales están reglamentados en la Resolución 706 de 2016 y en el parágrafo 3° del artículo 4° de la Ley 716 de 2001, modificado por el Artículo 2° de la Ley 901 de 2004. Asi las cosas, previendo las consecuencias de quedar incluido en uno o ambos reportes, agradecemos a usted el pago oportuno y asi cumplir con las obligaciones de Ley.
A59: Nota: La deuda de las facturas relacionadas, no incluye deuda reclamada, en concordato, financiada, ni interés por mora. Estos se calculan diariamente y se liquidan el día que ingresa el pago efectivo de las facturas vencidas, considerando la tasa de interés vigente.
A65: FIRMA RECIBIDO: | E65: FECHA RECIBIDO:

Sheet GOB DEL CESAR
D1: FORMATO ENTREGA FACTURACIÓN ESPECIAL
J3: Rocio
A4: ALIADO COMERCIAL: | D4: INMEL | E4: REPARTIDOR ASIGNADO:
J5: =J6&D6&D10 -> Rocio Gutierrez OchoaGOBERNACION DEL CESARSALUD
A6: TITULAR DE PAGO: | D6: GOBERNACION DEL CESAR | J6: {=_xlfn.IFS(J3="Anyela","Anyela Maria Gutierrez Ochoa",J3="Dalila","Dalila Michela Bracho Acosta",J3="Ingrid","Ingrid Johana Giraldo Quinonez",J3="Paola","Paola De la Hoz Bastidas",J3="Roberto","Roberto Pavajeau Hernandez",J3="Rocio","Rocio Gutierrez Ochoa",J3="Rosmeri","Rosmeri Rivera Rodriguez",J3="Yeisver","Yeisver Jimenéz Quiroz")} -> Rocio Gutierrez Ochoa
A8: DIRECCION: | D8: TR 18 19 85
A10: SEGMENTO / CUENTA: | D10: SALUD
A12: Nº | C12: NIC | D12: DESCRIPCION DE SUMINISTRO | E12: SIMB VAR | F12: IMPORTE MES | G12: DEUDA | H12: TOTAL
A13: 1 | B13: {=_xlfn._xlws.FILTER('R.V.'!K3:L2141,'R.V.'!K3:K2141=J5,"error")} -> #VALUE! | C13: 5352794 | D13: =IFERROR(VLOOKUP(C13,'R.V.'!B:D,3,0)," ") -> PROGRAMAS MEDICOS ESPECIAL | E13: =IFERROR(VLOOKUP($C13,INFO!$F:$AK,2,0)," ") -> 5352794324 | F13: =IFERROR(VLOOKUP(C13,INFO!F:T,11,0)," ") -> 34682070 | G13: =IFERROR(H13-F13," ") -> 0 | H13: =IFERROR(VLOOKUP(C13,INFO!$F:$AK,32,0)," ") -> 34682070
A14: 2 | D14: =IFERROR(VLOOKUP(C14,'R.V.'!B:D,3,0)," ") | E14: =IFERROR(VLOOKUP($C14,INFO!$F:$AK,2,0)," ") | F14: =IFERROR(VLOOKUP(C14,INFO!F:T,11,0)," ") | G14: =IFERROR(H14-F14," ") | H14: =IFERROR(VLOOKUP(C14,INFO!$F:$AK,32,0)," ")
A15: 3 | D15: =IFERROR(VLOOKUP(C15,'R.V.'!B:D,3,0)," ") | E15: =IFERROR(VLOOKUP($C15,INFO!$F:$AK,2,0)," ") | F15: =IFERROR(VLOOKUP(C15,INFO!F:T,11,0)," ") | G15: =IFERROR(H15-F15," ") | H15: =IFERROR(VLOOKUP(C15,INFO!$F:$AK,32,0)," ")
A16: 4 | D16: =IFERROR(VLOOKUP(C16,'R.V.'!B:D,3,0)," ") | E16: =IFERROR(VLOOKUP($C16,INFO!$F:$AK,2,0)," ") | F16: =IFERROR(VLOOKUP(C16,INFO!F:T,11,0)," ") | G16: =IFERROR(H16-F16," ") | H16: =IFERROR(VLOOKUP(C16,INFO!$F:$AK,32,0)," ")
A17: 5 | D17: =IFERROR(VLOOKUP(C17,'R.V.'!B:D,3,0)," ") | E17: =IFERROR(VLOOKUP($C17,INFO!$F:$AK,2,0)," ") | F17: =IFERROR(VLOOKUP(C17,INFO!F:T,11,0)," ") | G17: =IFERROR(H17-F17," ") | H17: =IFERROR(VLOOKUP(C17,INFO!$F:$AK,32,0)," ")
A18: 6 | D18: =IFERROR(VLOOKUP(C18,'R.V.'!B:D,3,0)," ") | E18: =IFERROR(VLOOKUP($C18,INFO!$F:$AK,2,0)," ") | F18: =IFERROR(VLOOKUP(C18,INFO!F:T,11,0)," ") | G18: =IFERROR(H18-F18," ") | H18: =IFERROR(VLOOKUP(C18,INFO!$F:$AK,32,0)," ")
A19: 7 | D19: =IFERROR(VLOOKUP(C19,'R.V.'!B:D,3,0)," ") | E19: =IFERROR(VLOOKUP($C19,INFO!$F:$AK,2,0)," ") | F19: =IFERROR(VLOOKUP(C19,INFO!F:T,11,0)," ") | G19: =IFERROR(H19-F19," ") | H19: =IFERROR(VLOOKUP(C19,INFO!$F:$AK,32,0)," ")
A20: 8 | D20: =IFERROR(VLOOKUP(C20,'R.V.'!B:D,3,0)," ") | E20: =IFERROR(VLOOKUP($C20,INFO!$F:$AK,2,0)," ") | F20: =IFERROR(VLOOKUP(C20,INFO!F:T,11,0)," ") | G20: =IFERROR(H20-F20," ") | H20: =IFERROR(VLOOKUP(C20,INFO!$F:$AK,32,0)," ")
A21: 9 | D21: =IFERROR(VLOOKUP(C21,'R.V.'!B:D,3,0)," ") | E21: =IFERROR(VLOOKUP($C21,INFO!$F:$AK,2,0)," ") | F21: =IFERROR(VLOOKUP(C21,INFO!F:T,11,0)," ") | G21: =IFERROR(H21-F21," ") | H21: =IFERROR(VLOOKUP(C21,INFO!$F:$AK,32,0)," ")
A22: 10 | D22: =IFERROR(VLOOKUP(C22,'R.V.'!B:D,3,0)," ") | E22: =IFERROR(VLOOKUP($C22,INFO!$F:$AK,2,0)," ") | F22: =IFERROR(VLOOKUP(C22,INFO!F:T,11,0)," ") | G22: =IFERROR(H22-F22," ") | H22: =IFERROR(VLOOKUP(C22,INFO!$F:$AK,32,0)," ")
A23: 11 | D23: =IFERROR(VLOOKUP(C23,'R.V.'!B:D,3,0)," ") | E23: =IFERROR(VLOOKUP($C23,INFO!$F:$AK,2,0)," ") | F23: =IFERROR(VLOOKUP(C23,INFO!F:T,11,0)," ") | G23: =IFERROR(H23-F23," ") | H23: =IFERROR(VLOOKUP(C23,INFO!$F:$AK,32,0)," ")
A24: 12 | D24: =IFERROR(VLOOKUP(C24,'R.V.'!B:D,3,0)," ") | E24: =IFERROR(VLOOKUP($C24,INFO!$F:$AK,2,0)," ") | F24: =IFERROR(VLOOKUP(C24,INFO!F:T,11,0)," ") | G24: =IFERROR(H24-F24," ") | H24: =IFERROR(VLOOKUP(C24,INFO!$F:$AK,32,0)," ")
A25: 13 | D25: =IFERROR(VLOOKUP(C25,'R.V.'!B:D,3,0)," ") | E25: =IFERROR(VLOOKUP($C25,INFO!$F:$AK,2,0)," ") | F25: =IFERROR(VLOOKUP(C25,INFO!F:T,11,0)," ") | G25: =IFERROR(H25-F25," ") | H25: =IFERROR(VLOOKUP(C25,INFO!$F:$AK,32,0)," ")
... A51: 39 | D51: =IFERROR(VLOOKUP(C51,'R.V.'!B:D,3,0)," ") | E51: =IFERROR(VLOOKUP($C51,INFO!$F:$AK,2,0)," ") | F51: =IFERROR(VLOOKUP(C51,INFO!F:T,11,0)," ") | G51: =IFERROR(H51-F51," ") | H51: =IFERROR(VLOOKUP(C51,INFO!$F:$AK,32,0)," ")
E52: TOTAL | F52: =SUM(F13:F51) -> 34682070 | G52: =SUM(G13:G51) -> 0 | H52: =SUM(H13:H51) -> 34682070
A54: A CARIBEMAR DE LA COSTA S.A.S. E.S.P., le son aplicables las normas que regulan el saneamiento contable en el sector público, por tanto, nos permitimos recordar la obligacion que nos asiste de reportar a la Contaduría General de la Nación, semestralmente el Boletín de Deudores Morosos del Estado - BDME - , y trimestralmente el informe de Recíprocas (Entidades oficiales), los cuales están reglamentados en la Resolución 706 de 2016 y en el parágrafo 3° del artículo 4° de la Ley 716 de 2001, modificado por el Artículo 2° de la Ley 901 de 2004. Asi las cosas, previendo las consecuencias de quedar incluido en uno o ambos reportes, agradecemos a usted el pago oportuno y asi cumplir con las obligaciones de Ley.
A59: Nota: La deuda de las facturas relacionadas, no incluye deuda reclamada, en concordato, financiada, ni interés por mora. Estos se calculan diariamente y se liquidan el día que ingresa el pago efectivo de las facturas vencidas, considerando la tasa de interés vigente.
A65: FIRMA RECIBIDO: | E65: FECHA RECIBIDO:

Sheet ENTREGA DIRECTA EJECUTIVOS
A1: EJECUTIVO | B1: NIC | C1: TITULAR DE PAGO | D1: DESCRIPCIÓN DE SUMINISTRO | E1: SEGMENTO_CUENTA | F1: DOBLE ENTREGA (SI/NO) | G1: Donde se entrega PAQUETE 1 | H1: Donde se entrega PAQUETE 2 | I1: OBSERVACION ADICIONAL | K1: filtro | L1: NIC
A2: Paola De la Hoz Bastidas | B2: 1413166 | C2: MUNICIPIO DE VALLEDUPAR | D2: ACUEDUCTO CGTO VALENCIA- CARRET VIA PUEBLOBELLO | E2: ACUEDUCTO | F2: NO | G2: CR 5 No.15- 65 Secretraia Gral _Alcaldia Muncipal | I2: Impresión y entrega direcata por Ventas -Territorial, para revisión previa de Facturación, en cumplimiento a compromisos ante la SSPD. | K2: Paola De la Hoz BastidasMUNICIPIO DE VALLEDUPARACUEDUCTO | L2: 1413166
A3: Paola De la Hoz Bastidas | B3: 5357495 | C3: MUNICIPIO DE VALLEDUPAR | D3: ACDTO CMTARIO LAS RAICES_CGTO LAS RAICES | E3: ACUEDUCTO | F3: NO | G3: CR 5 No.15- 65 Secretraia Gral _Alcaldia Muncipal | I3: Impresión y entrega direcata por Ventas -Territorial, para revisión previa de Facturación, en cumplimiento a compromisos ante la SSPD. | K3: Paola De la Hoz BastidasMUNICIPIO DE VALLEDUPARACUEDUCTO | L3: 5357495
A4: Paola De la Hoz Bastidas | B4: 5358999 | C4: MUNICIPIO DE VALLEDUPAR | D4: ACUEDUCTO GUACOCHE_CGTO GUACOCHE | E4: ACUEDUCTO | F4: NO | G4: CR 5 No.15- 65 Secretraia Gral _Alcaldia Muncipal | I4: Impresión y entrega direcata por Ventas -Territorial, para revisión previa de Facturación, en cumplimiento a compromisos ante la SSPD. | K4: Paola De la Hoz BastidasMUNICIPIO DE VALLEDUPARACUEDUCTO | L4: 5358999
A5: Paola De la Hoz Bastidas | B5: 5359176 | C5: MUNICIPIO DE VALLEDUPAR | D5: ACUEDUCTO BOMBA EL JABO_EL JAVO RURAL | E5: ACUEDUCTO | F5: NO | G5: CR 5 No.15- 65 Secretraia Gral _Alcaldia Muncipal | I5: Impresión y entrega direcata por Ventas -Territorial, para revisión previa de Facturación, en cumplimiento a compromisos ante la SSPD. | K5: Paola De la Hoz BastidasMUNICIPIO DE VALLEDUPARACUEDUCTO | L5: 5359176
A6: Paola De la Hoz Bastidas | B6: 5359669 | C6: MUNICIPIO DE VALLEDUPAR | D6: ACUEDUCTO LOS CALABAZOS_CGTO LOS CALABAZOS | E6: ACUEDUCTO | F6: NO | G6: CR 5 No.15- 65 Secretraia Gral _Alcaldia Muncipal | I6: Impresión y entrega direcata por Ventas -Territorial, para revisión previa de Facturación, en cumplimiento a compromisos ante la SSPD. | K6: Paola De la Hoz BastidasMUNICIPIO DE VALLEDUPARACUEDUCTO | L6: 5359669
A7: Paola De la Hoz Bastidas | B7: 5360243 | C7: MUNICIPIO DE VALLEDUPAR | D7: ACUEDUCTO AGUAS BLANCAS_CGTO AGUAS BLANCAS | E7: ACUEDUCTO | F7: NO | G7: CR 5 No.15- 65 Secretraia Gral _Alcaldia Muncipal | I7: Impresión y entrega direcata por Ventas -Territorial, para revisión previa de Facturación, en cumplimiento a compromisos ante la SSPD. | K7: Paola De la Hoz BastidasMUNICIPIO DE VALLEDUPARACUEDUCTO | L7: 5360243
A8: Paola De la Hoz Bastidas | B8: 5360245 | C8: MUNICIPIO DE VALLEDUPAR | D8: ACUEDUCTO AGUAS BLANCAS_CGTO AGUAS BLANCAS | E8: ACUEDUCTO | F8: NO | G8: CR 5 No.15- 65 Secretraia Gral _Alcaldia Muncipal | I8: Impresión y entrega direcata por Ventas -Territorial, para revisión previa de Facturación, en cumplimiento a compromisos ante la SSPD. | K8: Paola De la Hoz BastidasMUNICIPIO DE VALLEDUPARACUEDUCTO | L8: 5360245
A9: Paola De la Hoz Bastidas | B9: 5361891 | C9: MUNICIPIO DE VALLEDUPAR | D9: ACUEDUCTO GUAYMARAL_CGTO GUAIMARAL | E9: ACUEDUCTO | F9: NO | G9: CR 5 No.15- 65 Secretraia Gral _Alcaldia Muncipal | I9: Impresión y entrega direcata por Ventas -Territorial, para revisión previa de Facturación, en cumplimiento a compromisos ante la SSPD. | K9: Paola De la Hoz BastidasMUNICIPIO DE VALLEDUPARACUEDUCTO | L9: 5361891
A10: Paola De la Hoz Bastidas | B10: 5361969 | C10: MUNICIPIO DE VALLEDUPAR | D10: ACUEDUCTO SAN MARTIN_CGTO EL PERRO | E10: ACUEDUCTO | F10: NO | G10: CR 5 No.15- 65 Secretraia Gral _Alcaldia Muncipal | I10: Impresión y entrega direcata por Ventas -Territorial, para revisión previa de Facturación, en cumplimiento a compromisos ante la SSPD. | K10: Paola De la Hoz BastidasMUNICIPIO DE VALLEDUPARACUEDUCTO | L10: 5361969
A11: Paola De la Hoz Bastidas | B11: 6238148 | C11: MUNICIPIO DE VALLEDUPAR | D11: ACDTO BOMBA LA VEGA _CGTO LA VEGA ARRIBA | E11: ACUEDUCTO | F11: NO | G11: CR 5 No.15- 65 Secretraia Gral _Alcaldia Muncipal | I11: Impresión y entrega direcata por Ventas -Territorial, para revisión previa de Facturación, en cumplimiento a compromisos ante la SSPD. | K11: Paola De la Hoz BastidasMUNICIPIO DE VALLEDUPARACUEDUCTO | L11: 6238148
A12: Paola De la Hoz Bastidas | B12: 6634302 | C12: MUNICIPIO DE VALLEDUPAR | D12: ACUEDUCTO DE ATANQUEZ_CGTO ATANQUEZ | E12: ACUEDUCTO | F12: NO | G12: CR 5 No.15- 65 Secretraia Gral _Alcaldia Muncipal | I12: Impresión y entrega direcata por Ventas -Territorial, para revisión previa de Facturación, en cumplimiento a compromisos ante la SSPD. | K12: Paola De la Hoz BastidasMUNICIPIO DE VALLEDUPARACUEDUCTO | L12: 6634302
A13: Paola De la Hoz Bastidas | B13: 6634330 | C13: MUNICIPIO DE VALLEDUPAR | D13: POZOS PROFUNDOS LAS CASITAS_VALLEDUPAR | E13: ACUEDUCTO | F13: NO | G13: CR 5 No.15- 65 Secretraia Gral _Alcaldia Muncipal | I13: Impresión y entrega direcata por Ventas -Territorial, para revisión previa de Facturación, en cumplimiento a compromisos ante la SSPD. | K13: Paola De la Hoz BastidasMUNICIPIO DE VALLEDUPARACUEDUCTO | L13: 6634330
... A330: Paola De la Hoz Bastidas | B330: 7958047 | C330: MUNICIPIO DE VALLEDUPAR | D330: PARQUE LA PROVINCIA_VALLEDUPAR | E330: MERCABASTOS | F330: NO | G330: CR 5 No.15- 65 Secretraia Gral _Alcaldia Muncipal | I330: Impresión y entrega direcata por Ventas -Territorial, para revisión previa de Facturación, en cumplimiento a compromisos ante la SSPD. | K330: Paola De la Hoz BastidasMUNICIPIO DE VALLEDUPARMERCABASTOS | L330: 7958047

Sheet PENDIENTE X RELACION
A1: NIC
A2: 1042964
A3: 7807638
A4: 1004143
A5: 6826884
A6: 7716020
A7: 7891239
A8: 5803604
A9: 1004333
A10: 5824593
A11: 5851177
A12: 5302399
A13: 1021220
... A84: 1039109

Sheet Hoja1
A1: EJECUTIVO | B1: Rosmeri Rivera Rodriguez
A2: SEGMENTO_CUENTA | B2: CENTRALIZADA | M2: Paola___SUPERCEL_EU___ | O2: Roberto_ACUEDUCTO_DESCENTRALIZADO | Q2: Rocio_ACUEDUCTO | S2: Rosmeri_ACUEDUCTO_DESCENTRALIZADO
D3: Yeisver Jimenéz Quiroz | F3: Paola De la Hoz Bastidas | I3: Anyela EDUCACION | K3: Ingrid_ACUEDUCTO | M3: SUPERCELL | O3: Acsepal | Q3: ADMON PUBLICA COOP SERVICIOS PUBLICOS DE NUEVA GRANADA | S3: EMPAZ | U3: Yeisver_ACUEDUCTO_DESCENTRALIZADO
A4: Etiquetas de fila | D4: ACUEDUCTO_DESCENTRALIZADO | F4: ___SUPERCEL_EU___ | I4: HOSPITAL DE AGUSTIN CODAZZI | K4: MUNICIPIO DE PAILITAS | O4: Empresa de servicios publicos EMCOPEY | Q4: MUNICIPIO DE ARIGUANI | S4: ESPUMA ESP | U4: EMPRESA DE SERVICIOS PUBLICOS EMPOBOSCONIA
A5: Total general | D5: ACUEDUCTO_EMPASO_DESCENTRALIZADO | F5: __SIVA_SISTEMA_INTEGRADO_DE_TRANSPORTE | I5: HOSPITAL DE BECERRIL | K5: MUNICIPIO DE CHIRIGUANA | M5: Paola_EDUCACION | O5: Empresa de servicios publicos SERVISANANGEL | Q5: MUNICIPIO DE ASTREA
D6: CASA_DE_LA_CULTURA_BOSCO_DESCENTRALIZADO_ | F6: ACUEDUCTO | I6: HOSPITAL DE CURUMANI | K6: MUNICIPIO DE LA GLORIA | M6: FAMISANAR ENTIDAD PROMOTORA DE SALUD | Q6: MUNICIPIO DE CHIMICHAGUA | S6: Rosmeri_PRIVADO | U6: Yeisver_EDUCACION
D7: EDUCACION | F7: EDUCACION | I7: HOSPITAL EL SOCORRO | K7: MUNICIPIO DE PELAYA | M7: MUNICIPIO DE VALLEDUPAR | O7: Roberto_PRIVADO | S7: BBVA COLOMBIA SA | U7: HOSPITAL DE EL PASO HERNANDO QUINTERO BLANCO
D8: NOTARIA | F8: EMDUPAR | I8: HOSPITAL JORGE ISAAC RINCON TORRES | K8: MUNICIPIO DE TAMALAMEQUE | O8: FUNDACION MEMBRANA (Pueblito Arhuaco) | Q8: Rocio_OTROS | S8: AGROPECUARIA CAMPO VERDE | U8: HOSPITAL SAN JUAN BOSCO
D9: PRIVADO | F9: FONVISOCIAL | I9: MUNICIPIO DE AGUSTIN CODAZZI | M9: Paola_HEAD | Q9: GOBERNACION DEL CESAR | S9: ALIMENTOS FRESCOS | U9: MUNCIPIO DE EL PASO
D10: PROPIOS | F10: HEAD | I10: MUNICIPIO DE BECERRIL | M10: HOSPITAL EDUARDO ARREDONDO DAZA | O10: Roberto_ACUEDUCTO_CENTRALIZADO | Q10: GOBERNACION DEL CESAR- PARQUE LUDICO LAS FLORES LOC2 | S10: APARTA HOTEL CUERPOS | U10: MUNICIPIO DE BOSCONIA
F11: IDECESAR | I11: MUNICIPIO DE CURUMANI | K11: Ingrid_PRIVADO | O11: Municipio de Pueblo Bello | Q11: GOBERNACION DEL CESAR- PARQUE LUDICO LAS FLORES LOC3 | S11: APARTA HOTEL PUNTO G
F12: INDER | I12: MUNICIPIO DE LA JAGUA DE IBIRICO | K12: AGROSAVIA | M12: Paola_INDER_SEDE_PERMANENTE_12_DE_OCTUBRE_ | Q12: GOBERNACION DEL CESAR- PARQUE LUDICO LAS FLORES LOC4 | S12: ARANGO CARNES | U12: Yeisver_PROPIOS
F13: INDER_SEDE_PERMANENTE_12_DE_OCTUBRE_ | I13: MUNICIPIO DE SAN DIEGO | K13: APRESHI LTDA -CERA COLEY STEFANY | M13: INDER | O13: Roberto_PROPIOS | Q13: GOBERNACION DEL CESAR-PARQUE LUDICO LAS FLORES LOC1 | S13: AREAS COMUNES DEL TERMINAL | U13: MUNCIPIO DE EL PASO
A14: EJECUTIVO | B14: Anyela Maria Gutierrez Ochoa | F14: INTERASEO_S.A.E.S.P | K14: ASOC PADRES DE FAMILIA | O14: Municipio de Algarrobo | S14: ARROCERA LA MALENA | U14: MUNICIPIO DE BOSCONIA
D15: Rosmeri Rivera Rodriguez | F15: MERCABASTOS | K15: AUTOCENTRO SUPERMERCADO | M15: Paola_PRIVADO | O15: Municipio de El Copey | Q15: Rocio_ACUEDUCTO_DESCENTRALIZADO | S15: ARROCERA MANO DE DIOS
A16: Etiquetas de fila | D16: ACUEDUCTO_DESCENTRALIZADO | F16: PRIVADO | K16: BBVA COLOMBIA | M16: CGIO MANUELA BELTRAN | O16: Municipio de Pueblo Bello | Q16: ACUEDUCTO DESCENTRALIZADO ACUACHIN | S16: ARROCERA VICTOR GUERRA | U16: Yeisver_ACUEDUCTO_EMPASO_DESCENTRALIZADO
A17: ACUEDUCTO | D17: CONCEJO_DESCENTRALIZADO | F17: PROPIO_SIN_PARQUE | K17: CARLOS MURGAS GUERRERO | M17: COL CALLEJA REAL | O17: Municipio de San Angel | S17: BANAPALMA | U17: EMPRESA DE SERVICIOS PUBLICOS DE EL PASO EMPASO E.S.P
A18: ACUEDUCTO_DESCENTRALIZADO | D18: EDUCACION | I18: Anyela ACUEDUCTO | K18: CENTRO CIAL ORBE PLAZA ARCO 01 | M18: MR. HARRY SPA | Q18: Rocio_PROPIOS | S18: BANCO BOGOTA
A19: BOMBEROS_DESCENTRALIZADO | D19: PRIVADO | I19: MUNICIPIO DE CURUMANI | K19: CENTRO DE ATENCION PRIORITARIA EN SALUD, CAPS | M19: ADOLFO JEREMIAS MOLINA MOLINA | O19: Roberto_EDUCACION | Q19: AGENCIA COLOMBIANA PARA LA REINCORPORACION Y LA NORMALIZACION ARN | S19: BANCO DAVIVIENDA SA | U19: Yeisver_NOTARIA
A20: EDUCACION | D20: PROPIOS | I20: MUNICIPIO DE SAN DIEGO | K20: CENTRO DE SERVICIO LTDA | M20: ALMACEN CAÑAMO | O20: DIOCESIS DE VALLEDUPAR (CURIA) | Q20: ALMACEN CALZATODO SA | S20: BANCO POPULAR SA | U20: JAIME ROMERO AMADOR
A21: PROPIOS | K21: CERA COLEY STEFANY | M21: C.D.T. DEL CESAR FUNDACION CENTRO DE INVESTIGACION | O21: Hospital Camilo Villazon Pumarejo | Q21: ALMACEN GINO PASCALLY | S21: BAVARIA
A22: PROPIOS_LUMINARIAS | F22: Ingrid Johana Giraldo Quinonez | I22: Anyela SALUD | K22: COOGANASUR | M22: CEMENTERIO JARDINES | O22: Hospital Local de Algarrobo | Q22: ALMACENES CAÑAMO | S22: BORROSO ANABEL | U22: Yeisver_CASA_DE_LA_CULTURA_BOSCO_DESCENTRALIZADO_
A23: SALUD | F23: ACUEDUCTO | I23: MUNICIPIO DE AGUSTIN CODAZZI | K23: EPS SANITAS CC ORBE PLAZA FLORES | M23: CUCINARE SAS | O23: Hospital Local Sabanas de San Angel | Q23: ALMACENES FLAMINGO | S23: CAJA DE COMPENSACION FAMILIAR DEL CESAR | U23: INSTITUTO MUNICOPAL DE CULTURA DEPORTE Y RECERACION DEL MUNICIPAL DE BOSCONIACASA GRANDE
A24: Total general | F24: ACUEDUCTO_DESCENTRALIZADO | K24: ESTACION DOÑA EXI | M24: ESESCO | O24: Hospital San Roque de El Copey | Q24: ARCE SOCARRAS LUIS F | S24: CAMARA DE COMERCIO
D25: Rocio Gutierrez Ochoa | F25: EDUCACION | I25: Anyela ACUEDUCTO DESCENTRALIZADO | K25: GIL ALEJANDRO | M25: ESPECIAL MIGRACION COLOMBIA UNIDAD ADMINISTRATIVA | O25: Municipio de Algarrobo | Q25: ARN AGENCIA PARA LA REINTEGRACION | S25: CARCO
D26: ACUEDUCTO | F26: PRIVADO | I26: ACUACUR | K26: GRUPO AGROINDUSTRIAL HACIENDA LA GLORIA | M26: GLORIA YOLANDA OLIVEROS OSORIO | O26: Municipio de El Copey | Q26: AS Y MORON S.A.S. | S26: CASA INDIGENA LOS CAMPANOS | U26: Yeisver_PRIVADO
D27: ACUEDUCTO_DESCENTRALIZADO | F27: PROPIOS | I27: EMPOSANDIEGO | K27: HOTEL RESTAURANTE TRANSPORTADOR | M27: HOTEL URAK ALFONSO DEL CASTILLO OLMEDO | O27: Municipio de Pueblo Bello | Q27: ASISTENCIA MEDICA INMEDIATA | S27: CICELED | U27: AEROCIVIL
D28: EDUCACION | F28: SALUD | I28: MUNICIPIO DE AGUSTIN CODAZZI | K28: INSTITUTO COLOMBIANO AGROPECUARIO ICA | M28: INVERSIONES MACHIQUE | O28: Municipio de San Angel | Q28: BERMUDEZ DIANA | S28: CLINICA BUENOS AIRES SAS | U28: ANA MARTINEZ DE PADILLA
D29: OTROS | I29: MUNICIPIO DE BECERRIL | K29: INSTITUTO NACIONAL DE VIAS | M29: JANNA MOTOR?S.A.S | Q29: BIBLIOTECA RAFAEL CARRILLO LUQUEZ | S29: CLINICA MEDICOS SA | U29: AREOPUERTOS DE ORIENTE
D30: PROPIOS | I30: TRIPLE AAA DE LA JAGUA DE IBIRICO | K30: MARFIL IMPRESOS | M30: MEGA COLEGIO FRANCISCO DE PAULA | O30: Roberto_CENTRALIZADA | Q30: BRITO PARODI JOSE LUIS | S30: CLUB CAMPESTRE | U30: ASMETSALUD
D31: SALUD | K31: MEDICAS DEL CESAR CENTRO DE ESPECIALISTAS | M31: MEGACOLEGIO | O31: INDUSTRIA MILITAR INDUMIL | Q31: CAFÉ DON VALLE | S31: COMPARTA EPS COPERATIVA DE SALUD | U31: AUTOCHEVROLET
I32: Anyela PROPIOS | K32: QUIMIOSALUD | M32: PINTO DAVID MORENO | O32: SEGURIDAD | Q32: CAMAGUEY SAS | S32: COOPROFESORES | U32: AUTOTROPICAL S.A.S
I33: CONCEJO MUNICIPAL LA JAGUA DE IBIRICO | K33: RAMA JUDICIAL | M33: SAS HOTEL UCLA CENTER CONS EN GESTION FINANCIERA Y DE RES | Q33: CANCHA DE FUTBOL NVA GRANADA | S33: DUSAKAWI - IPS HOSPITAL | U33: BASCULA BOSCONIA
I34: MUNICIPIO DE AGUSTIN CODAZZI | K34: UNIDAD DE TRATAMIENTO DE DOLOR CARIBE SAS | Q34: CASINO ATLANTIS CC MAYALES | S34: DUSAKAWI IPS HOSPITAL | U34: CESAR VEGA
D35: Roberto Pavajeau Hernandez | F35: Dalila Michela Bracho Acosta | I35: MUNICIPIO DE BECERRIL | M35: Paola__SIVA_SISTEMA_INTEGRADO_DE_TRANSPORTE | Q35: CC GUATAPURI COCINAS VERDES CREATIVAS LOCAL 332 | S35: EFECTIVO LTDA | U35: CLINICA REGIONAL SINAIS VITAIS S.A.S DE ESPECIALISTAS
D36: ACUEDUCTO_CENTRALIZADO | F36: EMPRESA | I36: MUNICIPIO DE CURUMANI | K36: Ingrid_ACUEDUCTO_DESCENTRALIZADO | M36: SIVA | Q36: CENTRO COMERCIAL SANITAS | S36: ETICOS SERRANO GOMEZ | U36: FENOCO SA
D37: ACUEDUCTO_DESCENTRALIZADO | I37: MUNICIPIO DE LA JAGUA DE IBIRICO | K37: ACUEDUCTO DE SIMAÑA | Q37: CENTRO ORTOPEDICO DEL CESAS S.A.S. | S37: EUPARI HOTEL | U37: GASAN BOSCONIA
D38: EDUCACION | I38: MUNICIPIO DE SAN DIEGO | K38: DE PAILITAS EMPRESAS DE SERVICIO PUBLICOS | Q38: CESAR ANAYA | S38: FEDERACION NACIONAL DE ARROCEROS FEDEARROZ | U38: HOTEL LAS OLAS RUTA DEL SOL
D39: PRIVADO | I39: POLICIA NACIONAL | K39: EMPOGLORIA EPS EMPRESA DE SERVICIOS PUBLICOS DE LA GLORIA | M39: Paola_EMDUPAR | Q39: CHURRASCADA PARRILLA | S39: FUNDACION DE LA MUJER | U39: HOTEL PALMA DE MAYORCA
D40: PROPIOS | I40: REGISTRADURIA NACIONAL DEL ESTADO CIVIL | K40: PROHIDRIK SA ESP | M40: EMDUPAR | Q40: CILEDCO | S40: FUNDACION MEDICO PREVENTIVA | U40: INVERSIONES SANTANA
...

Sheet Analisis
G1: EJECUTIVO | H1: Anyela Maria Gutierrez Ochoa | N1: EJECUTIVO | O1: Anyela Maria Gutierrez Ochoa
G2: MUNICIPIO | H2: AGUSTIN CODAZZI | N2: MUNICIPIO | O2: AGUSTIN CODAZZI
G3: SEGMENTO EJECUTIVO | H3: (Todas) | N3: SEGMENTO EJECUTIVO | O3: ACUEDUCTO_DESCENTRALIZADO
G5: NIC | H5: DIRECCION DE ENTREGA REAL | I5: SIMB VAR | J5: IMPORTE | K5: SALDO VENCIDO | N5: NIC | O5: DIRECCION DE ENTREGA REAL | P5: SIMB VAR | Q5: IMPORTE | R5: SALDO VENCIDO
G6: 1034390 | H6: Alcaldia de Agustin Codazzi Calle 18 Cra. 15-93 | I6: 1034390065 | J6: 2585190 | K6: 2585190 | N6: 5803338 | O6: CLL6 CRA 4-17 | P6: 5803338336 | Q6: 4000910 | R6: 534271517
G7: 1048898 | H7: Alcaldia de Agustin Codazzi Calle 18 Cra. 15-93 | I7: 1048898063 | J7: 238180 | K7: 238180 | N7: 5827735 | O7: CLL6 CRA 4-17 | P7: 5827735325 | Q7: 5125720 | R7: 22941430
G8: 1048901 | H8: Alcaldia de Agustin Codazzi Calle 18 Cra. 15-93 | I8: 1048901065 | J8: 563200 | K8: 563200 | N8: Total general
G9: 1048906 | H9: Alcaldia de Agustin Codazzi Calle 18 Cra. 15-93 | I9: 1048906063 | J9: 2615720 | K9: 2615720
G10: 1063642 | H10: Alcaldia de Agustin Codazzi Calle 18 Cra. 15-93 | I10: 1063642060 | J10: 3112250 | K10: 3112250
G11: 1067280 | H11: Alcaldia de Agustin Codazzi Calle 18 Cra. 15-93 | I11: 1067280050 | J11: 740650 | K11: 740650
G12: 1080798 | H12: Alcaldia de Agustin Codazzi Calle 18 Cra. 15-93 | I12: 1080798055 | J12: 842170 | K12: 842170
G13: 1088785 | H13: Alcaldia de Agustin Codazzi Calle 18 Cra. 15-93 | I13: 1088785057 | J13: 247820 | K13: 247820
G14: 1088786 | H14: Alcaldia de Agustin Codazzi Calle 18 Cra. 15-93 | I14: 1088786055 | J14: 120650 | K14: 120650
G15: 1344722 | H15: Alcaldia de Agustin Codazzi Calle 18 Cra. 15-93 | I15: 1344722027 | J15: 5491580 | K15: 5491580
G16: 1379384 | H16: Alcaldia de Agustin Codazzi Calle 18 Cra. 15-93 | I16: 1379384018 | J16: 1667330 | K16: 1667330
G17: 1379392 | H17: Alcaldia de Agustin Codazzi Calle 18 Cra. 15-93 | I17: 1379392018 | J17: 1667330 | K17: 1667330
G18: 1379396 | H18: Alcaldia de Agustin Codazzi Calle 18 Cra. 15-93 | I18: 1379396018 | J18: 1570770 | K18: 1570770
G19: 1379400 | H19: Alcaldia de Agustin Codazzi Calle 18 Cra. 15-93 | I19: 1379400017 | J19: 217110 | K19: 217110
G20: 1379404 | H20: Alcaldia de Agustin Codazzi Calle 18 Cra. 15-93 | I20: 1379404017 | J20: 181280 | K20: 181280
... G87: 7925626 | H87: Alcaldia de Agustin Codazzi Calle 18 Cra. 15-93 | I87: 7925626103 | J87: 5527410 | K87: 5527410
G88: Total general

Sheet Hoja2
A3: DIRECCION DE ENTREGA REAL | B3: TITULAR DE PAGO | C3: Cuenta de DIRECCION DE ENTREGA REAL
A4: CALLE 7 No 6 - 04 Barrio Fundacion - Hospital Tamalameque | B4: HOSPITAL TAMALAMEQUE | C4: 2
A5: tesoreria@agroindustriasjmd.com | B5: AGROINDUSTRIAS JMD Y | C5: 7
A6: Alcaldia de Agustin Codazzi Calle 18 Cra. 15-93 | B6: MUNICIPIO DE AGUSTIN | C6: 82
A7: Alcaldia de Curumani CLL 7 No.16-36 | B7: ACUACUR ESP | C7: 1
A8: Alcaldia de Curumani CLL 7 No.16-36 | B8: MUNICIPIO DE CURUMAN | C8: 68
A9: AREOPUERTO ALFONSO LOPEZ/VALLEDUPAR | B9: AEROCIVIL | C9: 3
A10: CALLE 10 # 22 - 52 EL COPEY | B10: EMPRESA DE SERVICIOS | C10: 2
A11: Calle 10 No. 10 - 75 - Hospital Francisco Canossa | B11: HOSPITAL FRANCISCO C | C11: 2
A12: CALLE 13 16A-35 - CODAZZI | B12: ALIMENTOS FRESCOS DE | C12: 1
A13: Calle 2 #8-56, Barrio Aríguani, Pueblo Bello | B13: FUNDACION MEMBRANA | C13: 1
A14: CALLE 2 No 5 A -75 Barrio El Centro - Alcaldia Municipal | B14: EMPRESA DE SERVICIOS | C14: 4
A15: CALLE 2 No 5 A -75 Barrio El Centro - Alcaldia Municipal | B15: MUNICIPIO DE LA GLOR | C15: 23
... A312: Vía Troncal del Oriente KM 7 | B312: POLICIA NACIONAL | C312: 1
A313: Total general | C313: 1992

Sheet INFO
A1: NIC | B1: FECHA EMISION | C1: NOMBRE DEL CLIENTE | D1: TITULAR DE PAGO | E1: DIRECCION DE LA CUENTA | F1: NIC2 | G1: SIMB VAR | H1: NIF | I1: NIS-RAD | J1: UNIC | K1: RUTA | L1: ITIN | M1: F. LECTURA | N1: TAR | O1: DESCRIPCION TARIFA | P1: IMPORTE | Q1: CSMO.KWH | R1: IMPORTE KWH | S1: POSICION | T1: SEC. ORDEN | U1: F. PAGO OPORTUNO | V1: MUNICIPIO | W1: TIPO DE MEDIDA | X1: PROPIEDAD DEL ACTIVO | Y1: FOES | Z1: DIAS FACTURADOS | AA1: ORDENADO (SI / NO) | AB1: CONSECUTIVO PDF | AC1: CENTRO DE IMPRESION | AD1: EXCLUIR (NO / VIRTUAL / ECA) | AE1: CLIENTE DISPERSO (SI / NO / CENTRALIZADA) | AF1: NOMBRE INFO | AG1: TIPO CLIENTE | AH1: CIIU | AI1: FECHA LECTURA INICIAL | AJ1: CIRCUITO | AK1: SALDO VENCIDO | AL1: OBSERVACION FACTURA | AM1: CENTRALIZADA | AN1: FISICOS | AO1: OBSERVACIONES VENTAS | AP1: EJECUTIVO | AQ1: DIRECCION DE ENTREGA REAL | AR1: SEGMENTO EJECUTIVO | AS1: DESCRIPCIÓN DE SUMINISTRO
A2: 5312024 | B2: 46111 | C2: COOPERATIVA COLANTA | D2: COMERCIALIZADORA COLANTA | E2: CENTRAL DE ABASTOS VALLEDUPAR DG 21 54-6 P 1 LOC 3B | F2: 5312024 | G2: 5312024295 | H2: 25308882 | I2: 5324022 | J2: 3110 | K2: 50 | L2: 2003 | M2: 46099 | N2: CZ1 | O2: Com (Sencilla Niv.1 ) Caribe | P2: 12452090 | Q2: 9480 | R2: 10506001 | T2: 63110EN0022531195500200502003000160 | U2: 46121 | V2: VALLEDUPAR | W2: NIVEL I | X2: Propiedad Empresa | Y2: MEDICION | Z2: 30 | AA2: SI | AB2: 1 | AC2: VALLEDUPAR | AD2: NO | AE2: NO | AF2: INFO_CONSOL_ESPECIALES | AG2: Comercial Liberalizado | AH2: Comercio al por menor en | AI2: 46069 | AJ2: VALLEDUPAR 2 | AK2: 12452090 | AL2: #N/A | AM2: #N/A | AN2: RECIBIDO | AO2: =_xlfn.XLOOKUP(Tabla1[[#This Row],[NIC]],'R.V.'!B:B,'R.V.'!I:I) -> 0 | AP2: =_xlfn.XLOOKUP(Tabla1[[#This Row],[NIC]],'R.V.'!B:B,'R.V.'!A:A) -> Dalila Michela Bracho Acosta | AQ2: =_xlfn.XLOOKUP(Tabla1[[#This Row],[NIC]],'R.V.'!B:B,'R.V.'!G:G) -> DG 21, 54 6 P1 LOC 3B CENTRAL DE ABASTOS | AR2: =_xlfn.XLOOKUP(Tabla1[[#This Row],[NIC]],'R.V.'!B:B,'R.V.'!E:E) -> EMPRESA | AS2: =VLOOKUP(Tabla1[[#This Row],[NIC]],'R.V.'!B:D,3,0) -> PRIVADO
A3: 5808658 | B3: 46111 | C3: GOBERNACION DE DE LA | D3: CENTRO EDUCATIVO EL PLAN | E3: EL PLAN RURAL EL PLAN CR 5 CL 5-55 | F3: 5808658 | G3: 5808658335 | H3: 25843478 | I3: 5808658 | J3: 3110 | K3: 60 | L3: 1 | M3: 46082 | N3: CZ1 | O3: Com (Sencilla Niv.1 ) Caribe | P3: 0 | Q3: 351 | R3: 368978.22 | T3: 63110EN0022565187900100600001010660 | V3: LA JAGUA DEL PILAR | W3: NIVEL I | X3: Propiedad Empresa | Y3: MEDICION | Z3: 28 | AA3: SI | AB3: 2 | AC3: VALLEDUPAR | AD3: NO | AE3: NO | AF3: INFO_CONSOL_ESPECIALES | AG3: Regulado Oficial Departamental | AH3: Educación | AI3: 46054 | AJ3: BALCON DEL CESAR 1 | AK3: 9954600 | AL3: #N/A | AM3: #N/A | AN3: RECIBIDO | AO3: =_xlfn.XLOOKUP(Tabla1[[#This Row],[NIC]],'R.V.'!B:B,'R.V.'!I:I) -> #N/A | AP3: =_xlfn.XLOOKUP(Tabla1[[#This Row],[NIC]],'R.V.'!B:B,'R.V.'!A:A) -> #N/A | AQ3: =_xlfn.XLOOKUP(Tabla1[[#This Row],[NIC]],'R.V.'!B:B,'R.V.'!G:G) -> #N/A | AR3: =_xlfn.XLOOKUP(Tabla1[[#This Row],[NIC]],'R.V.'!B:B,'R.V.'!E:E) -> #N/A | AS3: =VLOOKUP(Tabla1[[#This Row],[NIC]],'R.V.'!B:D,3,0) -> #N/A
A4: 6894764 | B4: 46111 | C4: ING CLINICAL CENTER | D4: ING CLINICAL CENTER SAS | E4: SANTA ANA VALLEDUPAR CL 16 17-261 | F4: 6894764 | G4: 6894764260 | H4: 34000167 | I4: 7723098 | J4: 3110 | K4: 50 | L4: 2005 | M4: 46106 | N4: CY2 | O4: Com(Mon.dbl.Tip2Niv.2)Caribe | P4: 114182410 | Q4: 112200 | R4: 98787898 | T4: 63110EN0023637806400100502005001270 | U4: 46121 | V4: VALLEDUPAR | W4: NIVEL II | X4: Propiedad Empresa | Y4: MEDICION | Z4: 32 | AA4: SI | AB4: 3 | AC4: VALLEDUPAR | AD4: NO | AE4: NO | AF4: INFO_CONSOL_ESPECIALES | AG4: Comercial Liberalizado | AH4: Actividades de hospitales | AI4: 46074 | AJ4: GUATAPURI 1 | AK4: 3916883097 | AL4: #N/A | AM4: #N/A | AN4: RECIBIDO | AO4: =_xlfn.XLOOKUP(Tabla1[[#This Row],[NIC]],'R.V.'!B:B,'R.V.'!I:I) -> 0 | AP4: =_xlfn.XLOOKUP(Tabla1[[#This Row],[NIC]],'R.V.'!B:B,'R.V.'!A:A) -> Rosmeri Rivera Rodriguez | AQ4: =_xlfn.XLOOKUP(Tabla1[[#This Row],[NIC]],'R.V.'!B:B,'R.V.'!G:G) -> CL 16 17 261 OFI 3 - VALLEDUPAR | AR4: =_xlfn.XLOOKUP(Tabla1[[#This Row],[NIC]],'R.V.'!B:B,'R.V.'!E:E) -> PRIVADO | AS4: =VLOOKUP(Tabla1[[#This Row],[NIC]],'R.V.'!B:D,3,0) -> ING CLINICAL CENTER
A5: 6908929 | B5: 46111 | C5: ING CLINICAL CENTER | D5: ING CLINICAL CENTER SAS | E5: SANTA ANA VALLEDUPAR CL 16 17-261 | F5: 6908929 | G5: 6908929237 | H5: 25320410 | I5: 7771911 | J5: 3110 | K5: 50 | L5: 2005 | M5: 46106 | N5: CZ1 | O5: Com (Sencilla Niv.1 ) Caribe | P5: 402110 | Q5: 320 | R5: 352211.2 | T5: 63110EN0023637806400100502005001270 | U5: 46121 | V5: VALLEDUPAR | W5: NIVEL I | X5: Propiedad Empresa | Y5: MEDICION | Z5: 32 | AA5: SI | AB5: 3 | AC5: VALLEDUPAR | AD5: NO | AE5: NO | AF5: INFO_CONSOL_ESPECIALES | AG5: Comercial Liberalizado | AH5: Actividades de administra | AI5: 46074 | AJ5: GUATAPURI 1 | AK5: 1646660 | AL5: #N/A | AM5: #N/A | AN5: RECIBIDO | AO5: =_xlfn.XLOOKUP(Tabla1[[#This Row],[NIC]],'R.V.'!B:B,'R.V.'!I:I) -> 0 | AP5: =_xlfn.XLOOKUP(Tabla1[[#This Row],[NIC]],'R.V.'!B:B,'R.V.'!A:A) -> Rosmeri Rivera Rodriguez | AQ5: =_xlfn.XLOOKUP(Tabla1[[#This Row],[NIC]],'R.V.'!B:B,'R.V.'!G:G) -> CL 16 17 261 OFI 3 - VALLEDUPAR | AR5: =_xlfn.XLOOKUP(Tabla1[[#This Row],[NIC]],'R.V.'!B:B,'R.V.'!E:E) -> PRIVADO | AS5: =VLOOKUP(Tabla1[[#This Row],[NIC]],'R.V.'!B:D,3,0) -> ING CLINICAL CENTER
